Workbook

Sheet All_India_Index_Upto_April2 (2)
A1: Sector | B1: Year | C1: Month | D1: Cereals and products | E1: Meat and fish | F1: Egg | G1: Milk and products | H1: Oils and fats | I1: Fruits | J1: Vegetables | K1: Pulses and products | L1: Sugar and Confectionery | M1: Spices | N1: Non-alcoholic beverages | O1: Prepared meals, snacks, sweets etc. | P1: Food and beverages | Q1: Pan, tobacco and intoxicants | R1: Clothing | S1: Footwear | T1: Clothing and footwear | U1: Housing | V1: Column4 | W1: Fuel and light | X1: Household goods and services | Y1: Health | Z1: Transport and communication | AA1: Recreation and amusement | AB1: Education | AC1: Personal care and effects | AD1: Miscellaneous | AE1: General index
A2: Rural | B2: 2013 | C2: January | D2: 107.5 | E2: 106.3 | F2: 108.1 | G2: 104.9 | H2: 106.1 | I2: 103.9 | J2: 101.9 | K2: 106.1 | L2: 106.8 | M2: 103.1 | N2: 104.8 | O2: 106.7 | P2: 105.5 | Q2: 105.1 | R2: 106.5 | S2: 105.8 | T2: 106.4 | U2: NA | W2: 105.5 | X2: 104.8 | Y2: 104 | Z2: 103.3 | AA2: 103.4 | AB2: 103.8 | AC2: 104.7 | AD2: 104 | AE2: 105.1
A3: Urban | B3: 2013 | C3: January | D3: 110.5 | E3: 109.1 | F3: 113 | G3: 103.6 | H3: 103.4 | I3: 102.3 | J3: 102.9 | K3: 105.8 | L3: 105.1 | M3: 101.8 | N3: 105.1 | O3: 107.9 | P3: 105.9 | Q3: 105.2 | R3: 105.9 | S3: 105 | T3: 105.8 | U3: 100.3 | W3: 105.4 | X3: 104.8 | Y3: 104.1 | Z3: 103.2 | AA3: 102.9 | AB3: 103.5 | AC3: 104.3 | AD3: 103.7 | AE3: 104
A4: Rural+Urban | B4: 2013 | C4: January | D4: 108.4 | E4: 107.3 | F4: 110 | G4: 104.4 | H4: 105.1 | I4: 103.2 | J4: 102.2 | K4: 106 | L4: 106.2 | M4: 102.7 | N4: 104.9 | O4: 107.3 | P4: 105.6 | Q4: 105.1 | R4: 106.3 | S4: 105.5 | T4: 106.2 | U4: 100.3 | W4: 105.5 | X4: 104.8 | Y4: 104 | Z4: 103.2 | AA4: 103.1 | AB4: 103.6 | AC4: 104.5 | AD4: 103.9 | AE4: 104.6
A5: Rural | B5: 2013 | C5: February | D5: 109.2 | E5: 108.7 | F5: 110.2 | G5: 105.4 | H5: 106.7 | I5: 104 | J5: 102.4 | K5: 105.9 | L5: 105.7 | M5: 103.1 | N5: 105.1 | O5: 107.7 | P5: 106.3 | Q5: 105.6 | R5: 107.1 | S5: 106.3 | T5: 107 | U5: NA | W5: 106.2 | X5: 105.2 | Y5: 104.4 | Z5: 103.9 | AA5: 104 | AB5: 104.1 | AC5: 104.6 | AD5: 104.4 | AE5: 105.8
A6: Urban | B6: 2013 | C6: February | D6: 112.9 | E6: 112.9 | F6: 116.9 | G6: 104 | H6: 103.5 | I6: 103.1 | J6: 104.9 | K6: 104.1 | L6: 103.8 | M6: 102.3 | N6: 106 | O6: 109 | P6: 107.2 | Q6: 106 | R6: 106.6 | S6: 105.5 | T6: 106.4 | U6: 100.4 | W6: 105.7 | X6: 105.2 | Y6: 104.7 | Z6: 104.4 | AA6: 103.3 | AB6: 103.7 | AC6: 104.3 | AD6: 104.3 | AE6: 104.7
A7: Rural+Urban | B7: 2013 | C7: February | D7: 110.4 | E7: 110.2 | F7: 112.8 | G7: 104.9 | H7: 105.5 | I7: 103.6 | J7: 103.2 | K7: 105.3 | L7: 105.1 | M7: 102.8 | N7: 105.5 | O7: 108.3 | P7: 106.6 | Q7: 105.7 | R7: 106.9 | S7: 106 | T7: 106.8 | U7: 100.4 | W7: 106 | X7: 105.2 | Y7: 104.5 | Z7: 104.2 | AA7: 103.6 | AB7: 103.9 | AC7: 104.5 | AD7: 104.4 | AE7: 105.3
A8: Rural | B8: 2013 | C8: March | D8: 110.2 | E8: 108.8 | F8: 109.9 | G8: 105.6 | H8: 106.2 | I8: 105.7 | J8: 101.4 | K8: 105.7 | L8: 105 | M8: 103.3 | N8: 105.6 | O8: 108.2 | P8: 106.6 | Q8: 106.5 | R8: 107.6 | S8: 106.8 | T8: 107.5 | U8: NA | W8: 106.1 | X8: 105.6 | Y8: 104.7 | Z8: 104.6 | AA8: 104 | AB8: 104.3 | AC8: 104.3 | AD8: 104.6 | AE8: 106
A9: Urban | B9: 2013 | C9: March | D9: 113.9 | E9: 111.4 | F9: 113.2 | G9: 104.3 | H9: 102.7 | I9: 104.9 | J9: 103.8 | K9: 103.5 | L9: 102.6 | M9: 102.4 | N9: 107 | O9: 109.8 | P9: 107.3 | Q9: 106.8 | R9: 107.2 | S9: 106 | T9: 107 | U9: 100.4 | W9: 106 | X9: 105.7 | Y9: 105.2 | Z9: 105.5 | AA9: 103.5 | AB9: 103.8 | AC9: 104.2 | AD9: 104.9 | AE9: 105
A10: Rural+Urban | B10: 2013 | C10: March | D10: 111.4 | E10: 109.7 | F10: 111.2 | G10: 105.1 | H10: 104.9 | I10: 105.3 | J10: 102.2 | K10: 105 | L10: 104.2 | M10: 103 | N10: 106.2 | O10: 108.9 | P10: 106.9 | Q10: 106.6 | R10: 107.4 | S10: 106.5 | T10: 107.3 | U10: 100.4 | W10: 106.1 | X10: 105.6 | Y10: 104.9 | Z10: 105.1 | AA10: 103.7 | AB10: 104 | AC10: 104.3 | AD10: 104.7 | AE10: 105.5
A11: Rural | B11: 2013 | C11: April | D11: 110.2 | E11: 109.5 | F11: 106.9 | G11: 106.3 | H11: 105.7 | I11: 108.3 | J11: 103.4 | K11: 105.7 | L11: 104.2 | M11: 103.2 | N11: 106.5 | O11: 108.8 | P11: 107.1 | Q11: 107.1 | R11: 108.1 | S11: 107.4 | T11: 108 | U11: NA | W11: 106.5 | X11: 106.1 | Y11: 105.1 | Z11: 104.4 | AA11: 104.5 | AB11: 104.8 | AC11: 102.7 | AD11: 104.6 | AE11: 106.4
A12: Urban | B12: 2013 | C12: April | D12: 114.6 | E12: 113.4 | F12: 106 | G12: 104.7 | H12: 102.1 | I12: 109.5 | J12: 109.7 | K12: 104.6 | L12: 102 | M12: 103.5 | N12: 108.2 | O12: 110.6 | P12: 108.8 | Q12: 108.5 | R12: 107.9 | S12: 106.4 | T12: 107.7 | U12: 100.5 | W12: 106.4 | X12: 106.5 | Y12: 105.7 | Z12: 105 | AA12: 104 | AB12: 105.2 | AC12: 103.2 | AD12: 105.1 | AE12: 105.7
A13: Rural+Urban | B13: 2013 | C13: April | D13: 111.6 | E13: 110.9 | F13: 106.6 | G13: 105.7 | H13: 104.4 | I13: 108.9 | J13: 105.5 | K13: 105.3 | L13: 103.5 | M13: 103.3 | N13: 107.2 | O13: 109.6 | P13: 107.7 | Q13: 107.5 | R13: 108 | S13: 107 | T13: 107.9 | U13: 100.5 | W13: 106.5 | X13: 106.3 | Y13: 105.3 | Z13: 104.7 | AA13: 104.2 | AB13: 105 | AC13: 102.9 | AD13: 104.8 | AE13: 106.1
... A259: Rural+Urban | B259: 2020 | C259: March | D259: 145.1 | E259: 167 | F259: 148.1 | G259: 151.5 | H259: 131.2 | I259: 142.5 | J259: 157.3 | K259: 141.1 | L259: 113.2 | M259: 153.2 | N259: 136.7 | O259: 159.6 | P259: 148.9 | Q259: 171.2 | R259: 151.2 | S259: 141.9 | T259: 149.8 | U259: 154.5 | W259: 148.9 | X259: 146.4 | Y259: 152.3 | Z259: 129.9 | AA259: 143.7 | AB259: 156.1 | AC259: 145.2 | AD259: 143.8 | AE259: 148.6
A260: Rural | B260: 2020 | C260: April | D260: 147.2 | F260: 146.9 | G260: 155.6 | H260: 137.1 | I260: 147.3 | J260: 162.7 | K260: 150.2 | L260: 119.8 | M260: 158.7 | N260: 139.2 | P260: 150.1 | U260: NA | W260: 148.4 | Y260: 154.3
A261: Urban | B261: 2020 | C261: April | D261: 151.8 | F261: 151.9 | G261: 155.5 | H261: 131.6 | I261: 152.9 | J261: 180 | K261: 150.8 | L261: 121.2 | M261: 154 | N261: 133.5 | P261: 153.5 | U261: 155.6 | W261: 137.1 | Y261: 144.8
A262: Rural+Urban | B262: 2020 | C262: April | D262: 148.7 | F262: 148.8 | G262: 155.6 | H262: 135.1 | I262: 149.9 | J262: 168.6 | K262: 150.4 | L262: 120.3 | M262: 157.1 | N262: 136.8 | P262: 151.4 | U262: 155.6 | W262: 144.1 | Y262: 150.7
A263: Rural | B263: 2020 | C263: May | U263: NA
A264: Urban | B264: 2020 | C264: May | U264: NA
A265: Rural+Urban | B265: 2020 | C265: May | U265: NA
A266: Rural | B266: 2020 | C266: June | D266: 148.2 | E266: 190.3 | F266: 149.4 | G266: 153.3 | H266: 138.2 | I266: 143.2 | J266: 148.9 | K266: 150.3 | L266: 113.2 | M266: 159.8 | N266: 142.1 | O266: 161.8 | P266: 152.3 | Q266: 182.4 | R266: 154.7 | S266: 150 | T266: 154.1 | U266: NA | W266: 144.9 | X266: 151.7 | Y266: 158.2 | Z266: 141.4 | AA266: 153.2 | AB266: 161.8 | AC266: 151.2 | AD266: 151.7 | AE266: 152.7
A267: Urban | B267: 2020 | C267: June | D267: 152.7 | E267: 197 | F267: 154.6 | G267: 153.4 | H267: 132.9 | I267: 151.8 | J267: 171.2 | K267: 152 | L267: 116.3 | M267: 158.8 | N267: 135.6 | O267: 161.7 | P267: 157 | Q267: 186.7 | R267: 149.1 | S267: 136.6 | T267: 147.2 | U267: 154.7 | W267: 137.1 | X267: 140.4 | Y267: 148.1 | Z267: 129.3 | AA267: 144.5 | AB267: 152.5 | AC267: 152.2 | AD267: 142 | AE267: 150.8
A268: Rural+Urban | B268: 2020 | C268: June | D268: 149.6 | E268: 192.7 | F268: 151.4 | G268: 153.3 | H268: 136.3 | I268: 147.2 | J268: 156.5 | K268: 150.9 | L268: 114.2 | M268: 159.5 | N268: 139.4 | O268: 161.8 | P268: 154 | Q268: 183.5 | R268: 152.5 | S268: 144.4 | T268: 151.4 | U268: 154.7 | W268: 141.9 | X268: 146.4 | Y268: 154.4 | Z268: 135 | AA268: 148.3 | AB268: 156.4 | AC268: 151.6 | AD268: 147 | AE268: 151.8
A269: Rural | B269: 2020 | C269: July | D269: 148.2 | E269: 190.3 | F269: 149.4 | G269: 153.3 | H269: 138.2 | I269: 143.2 | J269: 148.9 | K269: 150.3 | L269: 113.2 | M269: 159.8 | N269: 142.1 | O269: 161.8 | P269: 152.3 | Q269: 182.4 | R269: 154.7 | S269: 150 | T269: 154.1 | U269: NA | W269: 144.9 | X269: 151.7 | Y269: 158.2 | Z269: 141.4 | AA269: 153.2 | AB269: 161.8 | AC269: 151.2 | AD269: 151.7 | AE269: 152.7
A270: Urban | B270: 2020 | C270: July | D270: 152.7 | E270: 197 | F270: 154.6 | G270: 153.4 | H270: 132.9 | I270: 151.8 | J270: 171.2 | K270: 152 | L270: 116.3 | M270: 158.8 | N270: 135.6 | O270: 161.7 | P270: 157 | Q270: 186.7 | R270: 149.1 | S270: 136.6 | T270: 147.2 | U270: 154.7 | W270: 137.1 | X270: 140.4 | Y270: 148.1 | Z270: 129.3 | AA270: 144.5 | AB270: 152.5 | AC270: 152.2 | AD270: 142 | AE270: 150.8
A271: Rural+Urban | B271: 2020 | C271: July | D271: 149.6 | E271: 192.7 | F271: 151.4 | G271: 153.3 | H271: 136.3 | I271: 147.2 | J271: 156.5 | K271: 150.9 | L271: 114.2 | M271: 159.5 | N271: 139.4 | O271: 161.8 | P271: 154 | Q271: 183.5 | R271: 152.5 | S271: 144.4 | T271: 151.4 | U271: 154.7 | W271: 141.9 | X271: 146.4 | Y271: 154.4 | Z271: 135 | AA271: 148.3 | AB271: 156.4 | AC271: 151.6 | AD271: 147 | AE271: 151.8
A272: Rural | B272: 2020 | C272: August | D272: 147.6 | E272: 187.2 | F272: 148.4 | G272: 153.3 | H272: 139.8 | I272: 146.9 | J272: 171 | K272: 149.9 | L272: 114.2 | M272: 160 | N272: 143.5 | O272: 161.5 | P272: 155.3 | Q272: 180.9 | R272: 155.1 | S272: 149.3 | T272: 154.3 | U272: NA | W272: 145.8 | X272: 151.9 | Y272: 158.8 | Z272: 143.6 | AA272: 152.2 | AB272: 162.7 | AC272: 153.6 | AD272: 153 | AE272: 154.7
A273: Urban | B273: 2020 | C273: August | D273: 151.6 | E273: 197.8 | F273: 154.5 | G273: 153.4 | H273: 133.4 | I273: 154.5 | J273: 191.9 | K273: 151.3 | L273: 116.8 | M273: 160 | N273: 136.5 | O273: 163.3 | P273: 159.9 | Q273: 187.2 | R273: 150 | S273: 135.2 | T273: 147.8 | U273: 155.5 | W273: 138.3 | X273: 144.5 | Y273: 148.7 | Z273: 133.9 | AA273: 141.2 | AB273: 155.5 | AC273: 155.2 | AD273: 144.8 | AE273: 152.9
A274: Rural+Urban | B274: 2020 | C274: August | D274: 148.9 | E274: 190.9 | F274: 150.8 | G274: 153.3 | H274: 137.4 | I274: 150.4 | J274: 178.1 | K274: 150.4 | L274: 115.1 | M274: 160 | N274: 140.6 | O274: 162.3 | P274: 157 | Q274: 182.6 | R274: 153.1 | S274: 143.4 | T274: 151.7 | U274: 155.5 | W274: 143 | X274: 148.4 | Y274: 155 | Z274: 138.5 | AA274: 146 | AB274: 158.5 | AC274: 154.3 | AD274: 149 | AE274: 153.9
A275: Rural | B275: 2020 | C275: September | D275: 146.9 | E275: 183.9 | F275: 149.5 | G275: 153.4 | H275: 140.4 | I275: 147 | J275: 178.8 | K275: 149.3 | L275: 115.1 | M275: 160 | N275: 145.4 | O275: 161.6 | P275: 156.1 | Q275: 182.9 | R275: 155.4 | S275: 149.9 | T275: 154.6 | U275: NA | W275: 146.4 | X275: 151.6 | Y275: 159.1 | Z275: 144.6 | AA275: 152.8 | AB275: 161.1 | AC275: 157.4 | AD275: 153.7 | AE275: 155.4
A276: Urban | B276: 2020 | C276: September | D276: 151.5 | E276: 193.1 | F276: 157.3 | G276: 153.9 | H276: 134.4 | I276: 155.4 | J276: 202 | K276: 150.8 | L276: 118.9 | M276: 160.9 | N276: 137.7 | O276: 164.4 | P276: 161.3 | Q276: 188.7 | R276: 150.2 | S276: 136.3 | T276: 148.1 | U276: 156.3 | W276: 137.2 | X276: 145.4 | Y276: 150 | Z276: 135.1 | AA276: 141.8 | AB276: 154.9 | AC276: 159.8 | AD276: 146 | AE276: 154
A277: Rural+Urban | B277: 2020 | C277: September | D277: 148.4 | E277: 187.1 | F277: 152.5 | G277: 153.6 | H277: 138.2 | I277: 150.9 | J277: 186.7 | K277: 149.8 | L277: 116.4 | M277: 160.3 | N277: 142.2 | O277: 162.9 | P277: 158 | Q277: 184.4 | R277: 153.4 | S277: 144.3 | T277: 152 | U277: 156.3 | W277: 142.9 | X277: 148.7 | Y277: 155.6 | Z277: 139.6 | AA277: 146.6 | AB277: 157.5 | AC277: 158.4 | AD277: 150 | AE277: 154.7
... A373: Rural+Urban | B373: 2023 | C373: May | D373: 173.7 | E373: 214.3 | F373: 173.2 | G373: 179.5 | H373: 170 | I373: 172.2 | J373: 161 | K373: 175.6 | L373: 122.7 | M373: 218 | N373: 173.4 | O373: 194.2 | P373: 179.1 | Q373: 201 | R373: 187.3 | S373: 179.7 | T373: 186.2 | U373: 175.6 | W373: 182.8 | X373: 175.2 | Y373: 185.7 | Z373: 164.8 | AA373: 171.2 | AB373: 177.1 | AC373: 185.2 | AD373: 175.7 | AE373: 179.1

Sheet Sheet1
A1: Sector | B1: Year | C1: Month | D1: Cereals and products | E1: Meat and fish | F1: Egg | G1: Milk and products | H1: Oils and fats | I1: Fruits | J1: Vegetables | K1: Pulses and products | L1: Sugar and Confectionery | M1: Spices | N1: Nonalcoholic beverages | O1: Prepared meals, scks, sweets etc. | P1: Food and beverages | Q1: Pan, tobacco and intoxicants | R1: food | S1: Clothing | T1: Footwear | U1: Clothing and footwear | V1: clothing | W1: Housing | X1: Fuel and light | Y1: Household goods and services | Z1: House items | AA1: Health | AB1: Personal care and effects | AC1: Health 2 | AD1: Transport and communication | AE1: Recreation and amusement | AF1: Travel | AG1: Education | AH1: Miscellaneous | AI1: General index | AJ1: Other
A2: Rural | B2: 2013 | C2: January | D2: 107.5 | E2: 106.3 | F2: 108.1 | G2: 104.9 | H2: 106.1 | I2: 103.9 | J2: 101.9 | K2: 106.1 | L2: 106.8 | M2: 103.1 | N2: 104.8 | O2: 106.7 | P2: 105.5 | Q2: 105.1 | R2: =AVERAGE(D2:Q2) -> 105.48571 | S2: 106.5 | T2: 105.8 | U2: 106.4 | V2: =AVERAGE(S2:U2) -> 106.23333 | W2: 139.2561 | X2: 105.5 | Y2: 104.8 | Z2: =AVERAGE(W2:Y2) -> 116.5187 | AA2: 104 | AB2: 104.7 | AC2: =AVERAGE(AA2:AB2) -> 104.35 | AD2: 103.3 | AE2: 103.4 | AF2: =AVERAGE(AD2:AE2) -> 103.35 | AG2: 103.8 | AH2: 104 | AI2: 105.1 | AJ2: =AVERAGE(AG2:AI2) -> 104.3
A3: Urban | B3: 2013 | C3: January | D3: 110.5 | E3: 109.1 | F3: 113 | G3: 103.6 | H3: 103.4 | I3: 102.3 | J3: 102.9 | K3: 105.8 | L3: 105.1 | M3: 101.8 | N3: 105.1 | O3: 107.9 | P3: 105.9 | Q3: 105.2 | R3: =AVERAGE(D3:Q3) -> 105.82857 | S3: 105.9 | T3: 105 | U3: 105.8 | V3: =AVERAGE(S3:U3) -> 105.56667 | W3: 100.3 | X3: 105.4 | Y3: 104.8 | Z3: =AVERAGE(W3:Y3) -> 103.5 | AA3: 104.1 | AB3: 104.3 | AC3: =AVERAGE(AA3:AB3) -> 104.2 | AD3: 103.2 | AE3: 102.9 | AF3: =AVERAGE(AD3:AE3) -> 103.05 | AG3: 103.5 | AH3: 103.7 | AI3: 104 | AJ3: =AVERAGE(AG3:AI3) -> 103.73333
A4: Rural+Urban | B4: 2013 | C4: January | D4: 108.4 | E4: 107.3 | F4: 110 | G4: 104.4 | H4: 105.1 | I4: 103.2 | J4: 102.2 | K4: 106 | L4: 106.2 | M4: 102.7 | N4: 104.9 | O4: 107.3 | P4: 105.6 | Q4: 105.1 | R4: =AVERAGE(D4:Q4) -> 105.6 | S4: 106.3 | T4: 105.5 | U4: 106.2 | V4: =AVERAGE(S4:U4) -> 106 | W4: 100.3 | X4: 105.5 | Y4: 104.8 | Z4: =AVERAGE(W4:Y4) -> 103.53333 | AA4: 104 | AB4: 104.5 | AC4: =AVERAGE(AA4:AB4) -> 104.25 | AD4: 103.2 | AE4: 103.1 | AF4: =AVERAGE(AD4:AE4) -> 103.15 | AG4: 103.6 | AH4: 103.9 | AI4: 104.6 | AJ4: =AVERAGE(AG4:AI4) -> 104.03333
A5: Rural | B5: 2013 | C5: February | D5: 109.2 | E5: 108.7 | F5: 110.2 | G5: 105.4 | H5: 106.7 | I5: 104 | J5: 102.4 | K5: 105.9 | L5: 105.7 | M5: 103.1 | N5: 105.1 | O5: 107.7 | P5: 106.3 | Q5: 105.6 | R5: =AVERAGE(D5:Q5) -> 106.14286 | S5: 107.1 | T5: 106.3 | U5: 107 | V5: =AVERAGE(S5:U5) -> 106.8 | W5: 100.4 | X5: 106.2 | Y5: 105.2 | Z5: =AVERAGE(W5:Y5) -> 103.93333 | AA5: 104.4 | AB5: 104.6 | AC5: =AVERAGE(AA5:AB5) -> 104.5 | AD5: 103.9 | AE5: 104 | AF5: =AVERAGE(AD5:AE5) -> 103.95 | AG5: 104.1 | AH5: 104.4 | AI5: 105.8 | AJ5: =AVERAGE(AG5:AI5) -> 104.76667
A6: Urban | B6: 2013 | C6: February | D6: 112.9 | E6: 112.9 | F6: 116.9 | G6: 104 | H6: 103.5 | I6: 103.1 | J6: 104.9 | K6: 104.1 | L6: 103.8 | M6: 102.3 | N6: 106 | O6: 109 | P6: 107.2 | Q6: 106 | R6: =AVERAGE(D6:Q6) -> 106.9 | S6: 106.6 | T6: 105.5 | U6: 106.4 | V6: =AVERAGE(S6:U6) -> 106.16667 | W6: 100.4 | X6: 105.7 | Y6: 105.2 | Z6: =AVERAGE(W6:Y6) -> 103.76667 | AA6: 104.7 | AB6: 104.3 | AC6: =AVERAGE(AA6:AB6) -> 104.5 | AD6: 104.4 | AE6: 103.3 | AF6: =AVERAGE(AD6:AE6) -> 103.85 | AG6: 103.7 | AH6: 104.3 | AI6: 104.7 | AJ6: =AVERAGE(AG6:AI6) -> 104.23333
A7: Rural+Urban | B7: 2013 | C7: February | D7: 110.4 | E7: 110.2 | F7: 112.8 | G7: 104.9 | H7: 105.5 | I7: 103.6 | J7: 103.2 | K7: 105.3 | L7: 105.1 | M7: 102.8 | N7: 105.5 | O7: 108.3 | P7: 106.6 | Q7: 105.7 | R7: =AVERAGE(D7:Q7) -> 106.42143 | S7: 106.9 | T7: 106 | U7: 106.8 | V7: =AVERAGE(S7:U7) -> 106.56667 | W7: 100.4 | X7: 106 | Y7: 105.2 | Z7: =AVERAGE(W7:Y7) -> 103.86667 | AA7: 104.5 | AB7: 104.5 | AC7: =AVERAGE(AA7:AB7) -> 104.5 | AD7: 104.2 | AE7: 103.6 | AF7: =AVERAGE(AD7:AE7) -> 103.9 | AG7: 103.9 | AH7: 104.4 | AI7: 105.3 | AJ7: =AVERAGE(AG7:AI7) -> 104.53333
A8: Rural | B8: 2013 | C8: March | D8: 110.2 | E8: 108.8 | F8: 109.9 | G8: 105.6 | H8: 106.2 | I8: 105.7 | J8: 101.4 | K8: 105.7 | L8: 105 | M8: 103.3 | N8: 105.6 | O8: 108.2 | P8: 106.6 | Q8: 106.5 | R8: =AVERAGE(D8:Q8) -> 106.33571 | S8: 107.6 | T8: 106.8 | U8: 107.5 | V8: =AVERAGE(S8:U8) -> 107.3 | W8: 100.4 | X8: 106.1 | Y8: 105.6 | Z8: =AVERAGE(W8:Y8) -> 104.03333 | AA8: 104.7 | AB8: 104.3 | AC8: =AVERAGE(AA8:AB8) -> 104.5 | AD8: 104.6 | AE8: 104 | AF8: =AVERAGE(AD8:AE8) -> 104.3 | AG8: 104.3 | AH8: 104.6 | AI8: 106 | AJ8: =AVERAGE(AG8:AI8) -> 104.96667
A9: Urban | B9: 2013 | C9: March | D9: 113.9 | E9: 111.4 | F9: 113.2 | G9: 104.3 | H9: 102.7 | I9: 104.9 | J9: 103.8 | K9: 103.5 | L9: 102.6 | M9: 102.4 | N9: 107 | O9: 109.8 | P9: 107.3 | Q9: 106.8 | R9: =AVERAGE(D9:Q9) -> 106.68571 | S9: 107.2 | T9: 106 | U9: 107 | V9: =AVERAGE(S9:U9) -> 106.73333 | W9: 100.5 | X9: 106 | Y9: 105.7 | Z9: =AVERAGE(W9:Y9) -> 104.06667 | AA9: 105.2 | AB9: 104.2 | AC9: =AVERAGE(AA9:AB9) -> 104.7 | AD9: 105.5 | AE9: 103.5 | AF9: =AVERAGE(AD9:AE9) -> 104.5 | AG9: 103.8 | AH9: 104.9 | AI9: 105 | AJ9: =AVERAGE(AG9:AI9) -> 104.56667
A10: Rural+Urban | B10: 2013 | C10: March | D10: 111.4 | E10: 109.7 | F10: 111.2 | G10: 105.1 | H10: 104.9 | I10: 105.3 | J10: 102.2 | K10: 105 | L10: 104.2 | M10: 103 | N10: 106.2 | O10: 108.9 | P10: 106.9 | Q10: 106.6 | R10: =AVERAGE(D10:Q10) -> 106.47143 | S10: 107.4 | T10: 106.5 | U10: 107.3 | V10: =AVERAGE(S10:U10) -> 107.06667 | W10: 100.5 | X10: 106.1 | Y10: 105.6 | Z10: =AVERAGE(W10:Y10) -> 104.06667 | AA10: 104.9 | AB10: 104.3 | AC10: =AVERAGE(AA10:AB10) -> 104.6 | AD10: 105.1 | AE10: 103.7 | AF10: =AVERAGE(AD10:AE10) -> 104.4 | AG10: 104 | AH10: 104.7 | AI10: 105.5 | AJ10: =AVERAGE(AG10:AI10) -> 104.73333
A11: Rural | B11: 2013 | C11: April | D11: 110.2 | E11: 109.5 | F11: 106.9 | G11: 106.3 | H11: 105.7 | I11: 108.3 | J11: 103.4 | K11: 105.7 | L11: 104.2 | M11: 103.2 | N11: 106.5 | O11: 108.8 | P11: 107.1 | Q11: 107.1 | R11: =AVERAGE(D11:Q11) -> 106.63571 | S11: 108.1 | T11: 107.4 | U11: 108 | V11: =AVERAGE(S11:U11) -> 107.83333 | W11: 100.5 | X11: 106.5 | Y11: 106.1 | Z11: =AVERAGE(W11:Y11) -> 104.36667 | AA11: 105.1 | AB11: 102.7 | AC11: =AVERAGE(AA11:AB11) -> 103.9 | AD11: 104.4 | AE11: 104.5 | AF11: =AVERAGE(AD11:AE11) -> 104.45 | AG11: 104.8 | AH11: 104.6 | AI11: 106.4 | AJ11: =AVERAGE(AG11:AI11) -> 105.26667
A12: Urban | B12: 2013 | C12: April | D12: 114.6 | E12: 113.4 | F12: 106 | G12: 104.7 | H12: 102.1 | I12: 109.5 | J12: 109.7 | K12: 104.6 | L12: 102 | M12: 103.5 | N12: 108.2 | O12: 110.6 | P12: 108.8 | Q12: 108.5 | R12: =AVERAGE(D12:Q12) -> 107.58571 | S12: 107.9 | T12: 106.4 | U12: 107.7 | V12: =AVERAGE(S12:U12) -> 107.33333 | W12: 100.5 | X12: 106.4 | Y12: 106.5 | Z12: =AVERAGE(W12:Y12) -> 104.46667 | AA12: 105.7 | AB12: 103.2 | AC12: =AVERAGE(AA12:AB12) -> 104.45 | AD12: 105 | AE12: 104 | AF12: =AVERAGE(AD12:AE12) -> 104.5 | AG12: 105.2 | AH12: 105.1 | AI12: 105.7 | AJ12: =AVERAGE(AG12:AI12) -> 105.33333
A13: Rural+Urban | B13: 2013 | C13: April | D13: 111.6 | E13: 110.9 | F13: 106.6 | G13: 105.7 | H13: 104.4 | I13: 108.9 | J13: 105.5 | K13: 105.3 | L13: 103.5 | M13: 103.3 | N13: 107.2 | O13: 109.6 | P13: 107.7 | Q13: 107.5 | R13: =AVERAGE(D13:Q13) -> 106.97857 | S13: 108 | T13: 107 | U13: 107.9 | V13: =AVERAGE(S13:U13) -> 107.63333 | W13: 106.6 | X13: 106.5 | Y13: 106.3 | Z13: =AVERAGE(W13:Y13) -> 106.46667 | AA13: 105.3 | AB13: 102.9 | AC13: =AVERAGE(AA13:AB13) -> 104.1 | AD13: 104.7 | AE13: 104.2 | AF13: =AVERAGE(AD13:AE13) -> 104.45 | AG13: 105 | AH13: 104.8 | AI13: 106.1 | AJ13: =AVERAGE(AG13:AI13) -> 105.3
... A248: Rural | B248: 2019 | C248: December | D248: 142.8 | E248: 165.3 | F248: 149.5 | G248: 148.7 | H248: 127.5 | I248: 144.3 | J248: 209.5 | K248: 138.8 | L248: 113.6 | M248: 149.1 | N248: 139.3 | O248: 158.3 | P248: 154.3 | Q248: 167.8 | R248: =AVERAGE(D248:Q248) -> 150.62857 | S248: 152.6 | T248: 147.3 | U248: 151.9 | V248: =AVERAGE(S248:U248) -> 150.6 | W248: 175.6 | X248: 149.9 | Y248: 151.2 | Z248: =AVERAGE(W248:Y248) -> 158.9 | AA248: 154.8 | AB248: 140.6 | AC248: =AVERAGE(AA248:AB248) -> 147.7 | AD248: 135 | AE248: 149.5 | AF248: =AVERAGE(AD248:AE248) -> 142.25 | AG248: 161.1 | AH248: 147.1 | AI248: 152.3 | AJ248: =AVERAGE(AG248:AI248) -> 153.5
A249: Urban | B249: 2019 | C249: December | D249: 144.9 | E249: 164.5 | F249: 153.7 | G249: 147.5 | H249: 122.7 | I249: 147.2 | J249: 231.5 | K249: 137.2 | L249: 114.7 | M249: 148 | N249: 130.8 | O249: 157.7 | P249: 156.3 | Q249: 170.4 | R249: =AVERAGE(D249:Q249) -> 151.93571 | S249: 146.8 | T249: 132.8 | U249: 144.6 | V249: =AVERAGE(S249:U249) -> 141.4 | W249: 152.8 | X249: 133.6 | Y249: 139.8 | Z249: =AVERAGE(W249:Y249) -> 136.7 | AA249: 143.2 | AB249: 140.2 | AC249: =AVERAGE(AA249:AB249) -> 141.7 | AD249: 125.2 | AE249: 136.8 | AF249: =AVERAGE(AD249:AE249) -> 131 | AG249: 151.9 | AH249: 137.7 | AI249: 148.3 | AJ249: =AVERAGE(AG249:AI249) -> 145.96667
A250: Rural+Urban | B250: 2019 | C250: December | D250: 143.5 | E250: 165 | F250: 151.1 | G250: 148.3 | H250: 125.7 | I250: 145.7 | J250: 217 | K250: 138.3 | L250: 114 | M250: 148.7 | N250: 135.8 | O250: 158 | P250: 155 | Q250: 168.5 | R250: =AVERAGE(D250:Q250) -> 151.04286 | S250: 150.3 | T250: 141.3 | U250: 149 | V250: =AVERAGE(S250:U250) -> 146.86667 | W250: 152.8 | X250: 143.7 | Y250: 145.8 | Z250: =AVERAGE(W250:Y250) -> 144.75 | AA250: 150.4 | AB250: 140.4 | AC250: =AVERAGE(AA250:AB250) -> 145.4 | AD250: 129.8 | AE250: 142.3 | AF250: =AVERAGE(AD250:AE250) -> 136.05 | AG250: 155.7 | AH250: 142.5 | AI250: 150.4 | AJ250: =AVERAGE(AG250:AI250) -> 149.53333
A251: Rural | B251: 2020 | C251: January | D251: 143.7 | E251: 167.3 | F251: 153.5 | G251: 150.5 | H251: 132 | I251: 142.2 | J251: 191.5 | K251: 141.1 | L251: 113.8 | M251: 151.6 | N251: 139.7 | O251: 158.7 | P251: 153 | Q251: 168.6 | R251: =AVERAGE(D251:Q251) -> 150.51429 | S251: 152.8 | T251: 147.4 | U251: 152.1 | V251: =AVERAGE(S251:U251) -> 150.76667 | W251: 139.2561 | X251: 150.4 | Y251: 151.7 | Z251: =AVERAGE(W251:Y251) -> 147.1187 | AA251: 155.7 | AB251: 142.5 | AC251: =AVERAGE(AA251:AB251) -> 149.1 | AD251: 136.3 | AE251: 150.1 | AF251: =AVERAGE(AD251:AE251) -> 143.2 | AG251: 161.7 | AH251: 148.1 | AI251: 151.9 | AJ251: =AVERAGE(AG251:AI251) -> 153.9
A252: Urban | B252: 2020 | C252: January | D252: 145.6 | E252: 167.6 | F252: 157 | G252: 149.3 | H252: 126.3 | I252: 144.4 | J252: 207.8 | K252: 139.1 | L252: 114.8 | M252: 149.5 | N252: 131.1 | O252: 158.5 | P252: 154.4 | Q252: 170.8 | R252: =AVERAGE(D252:Q252) -> 151.15714 | S252: 147 | T252: 133.2 | U252: 144.9 | V252: =AVERAGE(S252:U252) -> 141.7 | W252: 153.9 | X252: 135.1 | Y252: 140.1 | Z252: =AVERAGE(W252:Y252) -> 137.6 | AA252: 143.8 | AB252: 142.1 | AC252: =AVERAGE(AA252:AB252) -> 142.95 | AD252: 126.1 | AE252: 137.2 | AF252: =AVERAGE(AD252:AE252) -> 131.65 | AG252: 152.1 | AH252: 138.4 | AI252: 148.2 | AJ252: =AVERAGE(AG252:AI252) -> 146.23333
A253: Rural+Urban | B253: 2020 | C253: January | D253: 144.3 | E253: 167.4 | F253: 154.9 | G253: 150.1 | H253: 129.9 | I253: 143.2 | J253: 197 | K253: 140.4 | L253: 114.1 | M253: 150.9 | N253: 136.1 | O253: 158.6 | P253: 153.5 | Q253: 169.2 | R253: =AVERAGE(D253:Q253) -> 150.68571 | S253: 150.5 | T253: 141.5 | U253: 149.2 | V253: =AVERAGE(S253:U253) -> 147.06667 | W253: 153.9 | X253: 144.6 | Y253: 146.2 | Z253: =AVERAGE(W253:Y253) -> 145.4 | AA253: 151.2 | AB253: 142.3 | AC253: =AVERAGE(AA253:AB253) -> 146.75 | AD253: 130.9 | AE253: 142.8 | AF253: =AVERAGE(AD253:AE253) -> 136.85 | AG253: 156.1 | AH253: 143.4 | AI253: 150.2 | AJ253: =AVERAGE(AG253:AI253) -> 149.9
A254: Rural | B254: 2020 | C254: February | D254: 144.2 | E254: 167.5 | F254: 150.9 | G254: 150.9 | H254: 133.7 | I254: 140.7 | J254: 165.1 | K254: 141.8 | L254: 113.1 | M254: 152.8 | N254: 140.1 | O254: 159.2 | P254: 149.8 | Q254: 169.4 | R254: =AVERAGE(D254:Q254) -> 148.51429 | S254: 153 | T254: 147.5 | U254: 152.3 | V254: =AVERAGE(S254:U254) -> 150.93333 | W254: 139.2561 | X254: 152.3 | Y254: 151.8 | Z254: =AVERAGE(W254:Y254) -> 147.78537 | AA254: 156.2 | AB254: 143.4 | AC254: =AVERAGE(AA254:AB254) -> 149.8 | AD254: 136 | AE254: 150.4 | AF254: =AVERAGE(AD254:AE254) -> 143.2 | AG254: 161.9 | AH254: 148.4 | AI254: 150.4 | AJ254: =AVERAGE(AG254:AI254) -> 153.56667
A255: Urban | B255: 2020 | C255: February | D255: 146.2 | E255: 167.6 | F255: 153.1 | G255: 150.7 | H255: 127.4 | I255: 143.1 | J255: 181.7 | K255: 139.6 | L255: 114.6 | M255: 150.4 | N255: 131.5 | O255: 159 | P255: 151.7 | Q255: 172 | R255: =AVERAGE(D255:Q255) -> 149.18571 | S255: 147.3 | T255: 133.5 | U255: 145.2 | V255: =AVERAGE(S255:U255) -> 142 | W255: 154.8 | X255: 138.9 | Y255: 140.4 | Z255: =AVERAGE(W255:Y255) -> 139.65 | AA255: 144.4 | AB255: 143.5 | AC255: =AVERAGE(AA255:AB255) -> 143.95 | AD255: 125.2 | AE255: 137.7 | AF255: =AVERAGE(AD255:AE255) -> 131.45 | AG255: 152.2 | AH255: 138.4 | AI255: 147.7 | AJ255: =AVERAGE(AG255:AI255) -> 146.1
A256: Rural+Urban | B256: 2020 | C256: February | D256: 144.8 | E256: 167.5 | F256: 151.8 | G256: 150.8 | H256: 131.4 | I256: 141.8 | J256: 170.7 | K256: 141.1 | L256: 113.6 | M256: 152 | N256: 136.5 | O256: 159.1 | P256: 150.5 | Q256: 170.1 | R256: =AVERAGE(D256:Q256) -> 148.69286 | S256: 150.8 | T256: 141.7 | U256: 149.5 | V256: =AVERAGE(S256:U256) -> 147.33333 | W256: 154.8 | X256: 147.2 | Y256: 146.4 | Z256: =AVERAGE(W256:Y256) -> 146.8 | AA256: 151.7 | AB256: 143.4 | AC256: =AVERAGE(AA256:AB256) -> 147.55 | AD256: 130.3 | AE256: 143.2 | AF256: =AVERAGE(AD256:AE256) -> 136.75 | AG256: 156.2 | AH256: 143.6 | AI256: 149.1 | AJ256: =AVERAGE(AG256:AI256) -> 149.63333
A257: Rural | B257: 2020 | C257: March | D257: 144.4 | E257: 166.8 | F257: 147.6 | G257: 151.7 | H257: 133.3 | I257: 141.8 | J257: 152.3 | K257: 141.8 | L257: 112.6 | M257: 154 | N257: 140.1 | O257: 160 | P257: 148.2 | Q257: 170.5 | R257: =AVERAGE(D257:Q257) -> 147.50714 | S257: 153.4 | T257: 147.6 | U257: 152.5 | V257: =AVERAGE(S257:U257) -> 151.16667 | W257: 139.2561 | X257: 153.4 | Y257: 151.5 | Z257: =AVERAGE(W257:Y257) -> 148.05203 | AA257: 156.7 | AB257: 145.1 | AC257: =AVERAGE(AA257:AB257) -> 150.9 | AD257: 135.8 | AE257: 151.2 | AF257: =AVERAGE(AD257:AE257) -> 143.5 | AG257: 161.2 | AH257: 148.6 | AI257: 149.8 | AJ257: =AVERAGE(AG257:AI257) -> 153.2
A258: Urban | B258: 2020 | C258: March | D258: 146.5 | E258: 167.5 | F258: 148.9 | G258: 151.1 | H258: 127.5 | I258: 143.3 | J258: 167 | K258: 139.7 | L258: 114.4 | M258: 151.5 | N258: 131.9 | O258: 159.1 | P258: 150.1 | Q258: 173.3 | R258: =AVERAGE(D258:Q258) -> 147.98571 | S258: 147.7 | T258: 133.8 | U258: 145.6 | V258: =AVERAGE(S258:U258) -> 142.36667 | W258: 154.5 | X258: 141.4 | Y258: 140.8 | Z258: =AVERAGE(W258:Y258) -> 141.1 | AA258: 145 | AB258: 145.3 | AC258: =AVERAGE(AA258:AB258) -> 145.15 | AD258: 124.6 | AE258: 137.9 | AF258: =AVERAGE(AD258:AE258) -> 131.25 | AG258: 152.5 | AH258: 138.7 | AI258: 147.3 | AJ258: =AVERAGE(AG258:AI258) -> 146.16667
A259: Rural+Urban | B259: 2020 | C259: March | D259: 145.1 | E259: 167 | F259: 148.1 | G259: 151.5 | H259: 131.2 | I259: 142.5 | J259: 157.3 | K259: 141.1 | L259: 113.2 | M259: 153.2 | N259: 136.7 | O259: 159.6 | P259: 148.9 | Q259: 171.2 | R259: =AVERAGE(D259:Q259) -> 147.61429 | S259: 151.2 | T259: 141.9 | U259: 149.8 | V259: =AVERAGE(S259:U259) -> 147.63333 | W259: 154.5 | X259: 148.9 | Y259: 146.4 | Z259: =AVERAGE(W259:Y259) -> 147.65 | AA259: 152.3 | AB259: 145.2 | AC259: =AVERAGE(AA259:AB259) -> 148.75 | AD259: 129.9 | AE259: 143.7 | AF259: =AVERAGE(AD259:AE259) -> 136.8 | AG259: 156.1 | AH259: 143.8 | AI259: 148.6 | AJ259: =AVERAGE(AG259:AI259) -> 149.5
A260: Rural | B260: 2020 | C260: April | D260: 147.2 | E260: 156.26475 | F260: 146.9 | G260: 155.6 | H260: 137.1 | I260: 147.3 | J260: 162.7 | K260: 150.2 | L260: 119.8 | M260: 158.7 | N260: 139.2 | O260: 149.08716 | P260: 150.1 | Q260: 155.38579 | R260: =AVERAGE(D260:Q260) -> 148.25269 | S260: 142.66366 | T260: 135.97732 | U260: 141.67432 | V260: =AVERAGE(S260:U260) -> 140.1051 | W260: 139.2561 | X260: 148.4 | Y260: 136.68689 | Z260: =AVERAGE(W260:Y260) -> 141.44766 | AA260: 154.3 | AB260: 133.35 | AC260: =AVERAGE(AA260:AB260) -> 143.825 | AD260: 127.17049 | AE260: 133.8918 | AF260: =AVERAGE(AD260:AE260) -> 130.53115 | AG260: 141.13115 | AH260: 134.23579 | AI260: 139.56448 | AJ260: =AVERAGE(AG260:AI260) -> 138.31047
A261: Urban | B261: 2020 | C261: April | D261: 151.8 | E261: 156.26475 | F261: 151.9 | G261: 155.5 | H261: 131.6 | I261: 152.9 | J261: 180 | K261: 150.8 | L261: 121.2 | M261: 154 | N261: 133.5 | O261: 149.08716 | P261: 153.5 | Q261: 155.38579 | R261: =AVERAGE(D261:Q261) -> 149.81698 | S261: 142.66366 | T261: 135.97732 | U261: 141.67432 | V261: =AVERAGE(S261:U261) -> 140.1051 | W261: 155.6 | X261: 137.1 | Y261: 136.68689 | Z261: =AVERAGE(W261:Y261) -> 136.89344 | AA261: 144.8 | AB261: 133.35 | AC261: =AVERAGE(AA261:AB261) -> 139.075 | AD261: 127.17049 | AE261: 133.8918 | AF261: =AVERAGE(AD261:AE261) -> 130.53115 | AG261: 141.13115 | AH261: 134.23579 | AI261: 139.56448 | AJ261: =AVERAGE(AG261:AI261) -> 138.31047
A262: Rural+Urban | B262: 2020 | C262: April | D262: 148.7 | E262: 156.26475 | F262: 148.8 | G262: 155.6 | H262: 135.1 | I262: 149.9 | J262: 168.6 | K262: 150.4 | L262: 120.3 | M262: 157.1 | N262: 136.8 | O262: 149.08716 | P262: 151.4 | Q262: 155.38579 | R262: =AVERAGE(D262:Q262) -> 148.81698 | S262: 142.66366 | T262: 135.97732 | U262: 141.67432 | V262: =AVERAGE(S262:U262) -> 140.1051 | W262: 155.6 | X262: 144.1 | Y262: 136.68689 | Z262: =AVERAGE(W262:Y262) -> 140.39344 | AA262: 150.7 | AB262: 133.35 | AC262: =AVERAGE(AA262:AB262) -> 142.025 | AD262: 127.17049 | AE262: 133.8918 | AF262: =AVERAGE(AD262:AE262) -> 130.53115 | AG262: 141.13115 | AH262: 134.23579 | AI262: 139.56448 | AJ262: =AVERAGE(AG262:AI262) -> 138.31047
A263: Rural | B263: 2020 | C263: May | D263: 136.68591 | E263: 156.26475 | F263: 140.79756 | G263: 140.3252 | H263: 132.12629 | I263: 140.84092 | J263: 155.75203 | K263: 141.43089 | L263: 110.92493 | M263: 144.52222 | N263: 134.09295 | O263: 149.08716 | P263: 142.51003 | Q263: 155.38579 | R263: =AVERAGE(D263:Q263) -> 141.4819 | S263: 142.66366 | T263: 135.97732 | U263: 141.67432 | V263: =AVERAGE(S263:U263) -> 140.1051 | W263: 139.2561 | X263: 139.2561 | Y263: 136.68689 | Z263: =AVERAGE(W263:Y263) -> 138.39969 | AA263: 138.5168 | AB263: 133.35 | AC263: =AVERAGE(AA263:AB263) -> 135.9334 | AD263: 127.17049 | AE263: 133.8918 | AF263: =AVERAGE(AD263:AE263) -> 130.53115 | AG263: 141.13115 | AH263: 134.23579 | AI263: 139.56448 | AJ263: =AVERAGE(AG263:AI263) -> 138.31047
A264: Urban | B264: 2020 | C264: May | D264: 136.68591 | E264: 156.26475 | F264: 140.79756 | G264: 140.3252 | H264: 132.12629 | I264: 140.84092 | J264: 155.75203 | K264: 141.43089 | L264: 110.92493 | M264: 144.52222 | N264: 134.09295 | O264: 149.08716 | P264: 142.51003 | Q264: 155.38579 | R264: =AVERAGE(D264:Q264) -> 141.4819 | S264: 142.66366 | T264: 135.97732 | U264: 141.67432 | V264: =AVERAGE(S264:U264) -> 140.1051 | W264: 139.2561 | X264: 139.2561 | Y264: 136.68689 | Z264: =AVERAGE(W264:Y264) -> 138.39969 | AA264: 138.5168 | AB264: 133.35 | AC264: =AVERAGE(AA264:AB264) -> 135.9334 | AD264: 127.17049 | AE264: 133.8918 | AF264: =AVERAGE(AD264:AE264) -> 130.53115 | AG264: 141.13115 | AH264: 134.23579 | AI264: 139.56448 | AJ264: =AVERAGE(AG264:AI264) -> 138.31047
A265: Rural+Urban | B265: 2020 | C265: May | D265: 136.68591 | E265: 156.26475 | F265: 140.79756 | G265: 140.3252 | H265: 132.12629 | I265: 140.84092 | J265: 155.75203 | K265: 141.43089 | L265: 110.92493 | M265: 144.52222 | N265: 134.09295 | O265: 149.08716 | P265: 142.51003 | Q265: 155.38579 | R265: =AVERAGE(D265:Q265) -> 141.4819 | S265: 142.66366 | T265: 135.97732 | U265: 141.67432 | V265: =AVERAGE(S265:U265) -> 140.1051 | W265: 139.2561 | X265: 139.2561 | Y265: 136.68689 | Z265: =AVERAGE(W265:Y265) -> 138.39969 | AA265: 138.5168 | AB265: 133.35 | AC265: =AVERAGE(AA265:AB265) -> 135.9334 | AD265: 127.17049 | AE265: 133.8918 | AF265: =AVERAGE(AD265:AE265) -> 130.53115 | AG265: 141.13115 | AH265: 134.23579 | AI265: 139.56448 | AJ265: =AVERAGE(AG265:AI265) -> 138.31047
A266: Rural | B266: 2020 | C266: June | D266: 148.2 | E266: 190.3 | F266: 149.4 | G266: 153.3 | H266: 138.2 | I266: 143.2 | J266: 148.9 | K266: 150.3 | L266: 113.2 | M266: 159.8 | N266: 142.1 | O266: 161.8 | P266: 152.3 | Q266: 182.4 | R266: =AVERAGE(D266:Q266) -> 152.38571 | S266: 154.7 | T266: 150 | U266: 154.1 | V266: =AVERAGE(S266:U266) -> 152.93333 | W266: 139.2561 | X266: 144.9 | Y266: 151.7 | Z266: =AVERAGE(W266:Y266) -> 145.28537 | AA266: 158.2 | AB266: 151.2 | AC266: =AVERAGE(AA266:AB266) -> 154.7 | AD266: 141.4 | AE266: 153.2 | AF266: =AVERAGE(AD266:AE266) -> 147.3 | AG266: 161.8 | AH266: 151.7 | AI266: 152.7 | AJ266: =AVERAGE(AG266:AI266) -> 155.4
A267: Urban | B267: 2020 | C267: June | D267: 152.7 | E267: 197 | F267: 154.6 | G267: 153.4 | H267: 132.9 | I267: 151.8 | J267: 171.2 | K267: 152 | L267: 116.3 | M267: 158.8 | N267: 135.6 | O267: 161.7 | P267: 157 | Q267: 186.7 | R267: =AVERAGE(D267:Q267) -> 155.83571 | S267: 149.1 | T267: 136.6 | U267: 147.2 | V267: =AVERAGE(S267:U267) -> 144.3 | W267: 154.7 | X267: 137.1 | Y267: 140.4 | Z267: =AVERAGE(W267:Y267) -> 138.75 | AA267: 148.1 | AB267: 152.2 | AC267: =AVERAGE(AA267:AB267) -> 150.15 | AD267: 129.3 | AE267: 144.5 | AF267: =AVERAGE(AD267:AE267) -> 136.9 | AG267: 152.5 | AH267: 142 | AI267: 150.8 | AJ267: =AVERAGE(AG267:AI267) -> 148.43333
A268: Rural+Urban | B268: 2020 | C268: June | D268: 149.6 | E268: 192.7 | F268: 151.4 | G268: 153.3 | H268: 136.3 | I268: 147.2 | J268: 156.5 | K268: 150.9 | L268: 114.2 | M268: 159.5 | N268: 139.4 | O268: 161.8 | P268: 154 | Q268: 183.5 | R268: =AVERAGE(D268:Q268) -> 153.59286 | S268: 152.5 | T268: 144.4 | U268: 151.4 | V268: =AVERAGE(S268:U268) -> 149.43333 | W268: 154.7 | X268: 141.9 | Y268: 146.4 | Z268: =AVERAGE(W268:Y268) -> 144.15 | AA268: 154.4 | AB268: 151.6 | AC268: =AVERAGE(AA268:AB268) -> 153 | AD268: 135 | AE268: 148.3 | AF268: =AVERAGE(AD268:AE268) -> 141.65 | AG268: 156.4 | AH268: 147 | AI268: 151.8 | AJ268: =AVERAGE(AG268:AI268) -> 151.73333
A269: Rural | B269: 2020 | C269: July | D269: 148.2 | E269: 190.3 | F269: 149.4 | G269: 153.3 | H269: 138.2 | I269: 143.2 | J269: 148.9 | K269: 150.3 | L269: 113.2 | M269: 159.8 | N269: 142.1 | O269: 161.8 | P269: 152.3 | Q269: 182.4 | R269: =AVERAGE(D269:Q269) -> 152.38571 | S269: 154.7 | T269: 150 | U269: 154.1 | V269: =AVERAGE(S269:U269) -> 152.93333 | W269: 139.2561 | X269: 144.9 | Y269: 151.7 | Z269: =AVERAGE(W269:Y269) -> 145.28537 | AA269: 158.2 | AB269: 151.2 | AC269: =AVERAGE(AA269:AB269) -> 154.7 | AD269: 141.4 | AE269: 153.2 | AF269: =AVERAGE(AD269:AE269) -> 147.3 | AG269: 161.8 | AH269: 151.7 | AI269: 152.7 | AJ269: =AVERAGE(AG269:AI269) -> 155.4
A270: Urban | B270: 2020 | C270: July | D270: 152.7 | E270: 197 | F270: 154.6 | G270: 153.4 | H270: 132.9 | I270: 151.8 | J270: 171.2 | K270: 152 | L270: 116.3 | M270: 158.8 | N270: 135.6 | O270: 161.7 | P270: 157 | Q270: 186.7 | R270: =AVERAGE(D270:Q270) -> 155.83571 | S270: 149.1 | T270: 136.6 | U270: 147.2 | V270: =AVERAGE(S270:U270) -> 144.3 | W270: 154.7 | X270: 137.1 | Y270: 140.4 | Z270: =AVERAGE(W270:Y270) -> 138.75 | AA270: 148.1 | AB270: 152.2 | AC270: =AVERAGE(AA270:AB270) -> 150.15 | AD270: 129.3 | AE270: 144.5 | AF270: =AVERAGE(AD270:AE270) -> 136.9 | AG270: 152.5 | AH270: 142 | AI270: 150.8 | AJ270: =AVERAGE(AG270:AI270) -> 148.43333
A271: Rural+Urban | B271: 2020 | C271: July | D271: 149.6 | E271: 192.7 | F271: 151.4 | G271: 153.3 | H271: 136.3 | I271: 147.2 | J271: 156.5 | K271: 150.9 | L271: 114.2 | M271: 159.5 | N271: 139.4 | O271: 161.8 | P271: 154 | Q271: 183.5 | R271: =AVERAGE(D271:Q271) -> 153.59286 | S271: 152.5 | T271: 144.4 | U271: 151.4 | V271: =AVERAGE(S271:U271) -> 149.43333 | W271: 154.7 | X271: 141.9 | Y271: 146.4 | Z271: =AVERAGE(W271:Y271) -> 144.15 | AA271: 154.4 | AB271: 151.6 | AC271: =AVERAGE(AA271:AB271) -> 153 | AD271: 135 | AE271: 148.3 | AF271: =AVERAGE(AD271:AE271) -> 141.65 | AG271: 156.4 | AH271: 147 | AI271: 151.8 | AJ271: =AVERAGE(AG271:AI271) -> 151.73333
A272: Rural | B272: 2020 | C272: August | D272: 147.6 | E272: 187.2 | F272: 148.4 | G272: 153.3 | H272: 139.8 | I272: 146.9 | J272: 171 | K272: 149.9 | L272: 114.2 | M272: 160 | N272: 143.5 | O272: 161.5 | P272: 155.3 | Q272: 180.9 | R272: =AVERAGE(D272:Q272) -> 154.25 | S272: 155.1 | T272: 149.3 | U272: 154.3 | V272: =AVERAGE(S272:U272) -> 152.9 | W272: 139.2561 | X272: 145.8 | Y272: 151.9 | Z272: =AVERAGE(W272:Y272) -> 145.65203 | AA272: 158.8 | AB272: 153.6 | AC272: =AVERAGE(AA272:AB272) -> 156.2 | AD272: 143.6 | AE272: 152.2 | AF272: =AVERAGE(AD272:AE272) -> 147.9 | AG272: 162.7 | AH272: 153 | AI272: 154.7 | AJ272: =AVERAGE(AG272:AI272) -> 156.8
A273: Urban | B273: 2020 | C273: August | D273: 151.6 | E273: 197.8 | F273: 154.5 | G273: 153.4 | H273: 133.4 | I273: 154.5 | J273: 191.9 | K273: 151.3 | L273: 116.8 | M273: 160 | N273: 136.5 | O273: 163.3 | P273: 159.9 | Q273: 187.2 | R273: =AVERAGE(D273:Q273) -> 158.00714 | S273: 150 | T273: 135.2 | U273: 147.8 | V273: =AVERAGE(S273:U273) -> 144.33333 | W273: 155.5 | X273: 138.3 | Y273: 144.5 | Z273: =AVERAGE(W273:Y273) -> 141.4 | AA273: 148.7 | AB273: 155.2 | AC273: =AVERAGE(AA273:AB273) -> 151.95 | AD273: 133.9 | AE273: 141.2 | AF273: =AVERAGE(AD273:AE273) -> 137.55 | AG273: 155.5 | AH273: 144.8 | AI273: 152.9 | AJ273: =AVERAGE(AG273:AI273) -> 151.06667
A274: Rural+Urban | B274: 2020 | C274: August | D274: 148.9 | E274: 190.9 | F274: 150.8 | G274: 153.3 | H274: 137.4 | I274: 150.4 | J274: 178.1 | K274: 150.4 | L274: 115.1 | M274: 160 | N274: 140.6 | O274: 162.3 | P274: 157 | Q274: 182.6 | R274: =AVERAGE(D274:Q274) -> 155.55714 | S274: 153.1 | T274: 143.4 | U274: 151.7 | V274: =AVERAGE(S274:U274) -> 149.4 | W274: 155.5 | X274: 143 | Y274: 148.4 | Z274: =AVERAGE(W274:Y274) -> 145.7 | AA274: 155 | AB274: 154.3 | AC274: =AVERAGE(AA274:AB274) -> 154.65 | AD274: 138.5 | AE274: 146 | AF274: =AVERAGE(AD274:AE274) -> 142.25 | AG274: 158.5 | AH274: 149 | AI274: 153.9 | AJ274: =AVERAGE(AG274:AI274) -> 153.8
...

Sheet Solution 1
A1: Sector | B1: food | C1: clothing | D1: House items | E1: Health 2 | F1: Travel | G1: Other
A2: Rural | B2: 177.9 | C2: 189.96667 | D2: 167.18537 | E2: 186.35 | F2: 171.75 | G2: 179.86667 | H2: =SUM(B2:G2) -> 1073.0187
A3: Urban | B3: 181.37857 | C3: 176.23333 | D3: 176.75 | E3: 183.9 | F3: 164.8 | G3: 174.86667 | H3: =SUM(B3:G3) -> 1057.9286
A4: Rural+Urban | B4: 179.13571 | C4: 184.4 | D4: 179 | E4: 185.45 | F4: 168 | G4: 177.3 | H4: =SUM(B4:G4) -> 1073.2857
B5: =B2/H2 -> 0.16579394 | C5: =C2/H2 -> 0.17703947 | D5: =D2/H2 -> 0.15580844 | E5: =E2/H2 -> 0.17366892 | F5: =F2/H2 -> 0.16006245 | G5: =G2/H2 -> 0.16762678
B6: =B3/H3 -> 0.1714469 | C6: =C3/H3 -> 0.1665834 | D6: =D3/H3 -> 0.16707177 | E6: =E3/H3 -> 0.17383026 | F6: =F3/H3 -> 0.15577611 | G6: =G3/H3 -> 0.16529156
B7: =B4/H4 -> 0.16690403 | C7: =C4/H4 -> 0.17180886 | D7: =D4/H4 -> 0.16677759 | E7: =E4/H4 -> 0.17278717 | F7: =F4/H4 -> 0.15652868 | G7: =G4/H4 -> 0.16519366
A25: Based on the above graph,
A26: Clothing broader category has the highest contribution towards CPI calculation in rural.
A27: Health2(Health, Personal care and effects) | D27: broader category has the highest contribution towards CPI calculation in rural. | I27: in urban
A28: Health2(Health, Personal care and effects) | D28: broader category has the highest contribution towards CPI calculation in rural. | I28: in rural+urban.

Sheet Solution 2 
A1: Sector | B1: Year | C1: Month | D1: Cereals and products | E1: Meat and fish | F1: Egg | G1: Milk and products | H1: Oils and fats | I1: Fruits | J1: Vegetables | K1: Pulses and products | L1: Sugar and Confectionery | M1: Spices | N1: Nonalcoholic beverages | O1: Prepared meals, scks, sweets etc. | P1: Food and beverages | Q1: Pan, tobacco and intoxicants | R1: food | S1: Clothing | T1: Footwear | U1: Clothing and footwear | V1: clothing | W1: Housing | X1: Fuel and light | Y1: Household goods and services | Z1: House items | AA1: Health | AB1: Personal care and effects | AC1: Health 2 | AD1: Transport and communication | AE1: Recreation and amusement | AF1: Travel | AG1: Education | AH1: Miscellaneous | AI1: General index | AJ1: Other
A2: Rural+Urban | B2: 2017 | C2: January | D2: 132.8 | E2: 138.2 | F2: 132.2 | G2: 135.4 | H2: 119.1 | I2: 133 | J2: 119.4 | K2: 159.5 | L2: 115.6 | M2: 139.6 | N2: 126.6 | O2: 142.8 | P2: 133.1 | Q2: 143.8 | R2: 133.65 | S2: 136.6 | T2: 130.2 | U2: 135.6 | V2: 134.13333 | W2: 147.7 | X2: 126.8 | Y2: 129.4 | Z2: 134.63333 | AA2: 127.1 | AB2: 121.7 | AC2: 124.4 | AD2: 117 | AE2: 124.2 | AF2: 120.6 | AG2: 133.3 | AH2: 124.4 | AI2: 130.3 | AJ2: 129.33333
A3: Rural+Urban | B3: 2017 | C3: February | D3: 133.1 | E3: 138.8 | F3: 129.3 | G3: 135.8 | H3: 119.2 | I3: 135.3 | J3: 119.5 | K3: 152.2 | L3: 117.3 | M3: 138.7 | N3: 126.9 | O3: 143.2 | P3: 133 | Q3: 144.4 | R3: 133.33571 | S3: 136.8 | T3: 130.3 | U3: 135.9 | V3: 134.33333 | W3: 149 | X3: 127.9 | Y3: 129.7 | Z3: 135.53333 | AA3: 127.4 | AB3: 122.6 | AC3: 125 | AD3: 117.4 | AE3: 124.6 | AF3: 121 | AG3: 133.4 | AH3: 124.8 | AI3: 130.6 | AJ3: 129.6
A4: Rural+Urban | B4: 2017 | C4: March | D4: 133.3 | E4: 139 | F4: 128.6 | G4: 136.3 | H4: 118.8 | I4: 138.3 | J4: 120.5 | K4: 143.9 | L4: 118 | M4: 137.9 | N4: 127.2 | O4: 144 | P4: 133.1 | Q4: 145.1 | R4: 133.14286 | S4: 137.3 | T4: 130.6 | U4: 136.4 | V4: 134.76667 | W4: 150.1 | X4: 129.1 | Y4: 130.1 | Z4: 136.43333 | AA4: 127.8 | AB4: 122.6 | AC4: 125.2 | AD4: 117.6 | AE4: 125 | AF4: 121.3 | AG4: 133.8 | AH4: 125.1 | AI4: 130.9 | AJ4: 129.93333
A5: Rural+Urban | B5: 2017 | C5: April | D5: 133 | E5: 139.4 | F5: 126.1 | G5: 137.2 | H5: 118.4 | I5: 139.9 | J5: 123.4 | K5: 140.9 | L5: 118.5 | M5: 136.5 | N5: 127.4 | O5: 144.2 | P5: 133.5 | Q5: 145.4 | R5: 133.12857 | S5: 138 | T5: 131.1 | U5: 137 | V5: 135.36667 | W5: 150.6 | X5: 129.8 | Y5: 130.4 | Z5: 136.93333 | AA5: 128.1 | AB5: 123.1 | AC5: 125.6 | AD5: 116.6 | AE5: 125.1 | AF5: 120.85 | AG5: 134.5 | AH5: 125.1 | AI5: 131.1 | AJ5: 130.23333
A6: Rural+Urban | B6: 2017 | C6: May | D6: 132.9 | E6: 141.6 | F6: 126.3 | G6: 137.7 | H6: 118.1 | I6: 137.9 | J6: 125.6 | K6: 138.3 | L6: 119.4 | M6: 136 | N6: 127.6 | O6: 144.5 | P6: 133.7 | Q6: 146.2 | R6: 133.27143 | S6: 138.2 | T6: 131.4 | U6: 137.2 | V6: 135.6 | W6: 151.6 | X6: 129.4 | Y6: 130.9 | Z6: 137.3 | AA6: 128.4 | AB6: 123 | AC6: 125.7 | AD6: 116.7 | AE6: 125.7 | AF6: 121.2 | AG6: 134.8 | AH6: 125.3 | AI6: 131.4 | AJ6: 130.5
A7: Rural+Urban | B7: 2017 | C7: June | D7: 133.3 | E7: 145.5 | F7: 128.1 | G7: 138.1 | H7: 118.2 | I7: 139.2 | J7: 133.3 | K7: 136.2 | L7: 119.6 | M7: 135.3 | N7: 127.8 | O7: 144.9 | P7: 135.2 | Q7: 146.5 | R7: 134.37143 | S7: 138.5 | T7: 131.7 | U7: 137.5 | V7: 135.9 | W7: 153 | X7: 128.8 | Y7: 131.2 | Z7: 137.66667 | AA7: 128.5 | AB7: 123.4 | AC7: 125.95 | AD7: 116.5 | AE7: 125.9 | AF7: 121.2 | AG7: 135.4 | AH7: 125.5 | AI7: 132 | AJ7: 130.96667
A8: Rural+Urban | B8: 2017 | C8: July | D8: 133.6 | E8: 145.7 | F8: 129.6 | G8: 138.5 | H8: 118.1 | I8: 141.8 | J8: 159.5 | K8: 133.6 | L8: 120.5 | M8: 135.2 | N8: 128.5 | O8: 145.8 | P8: 139 | Q8: 148.2 | R8: 136.97143 | S8: 139.3 | T8: 132.1 | U8: 138.3 | V8: 136.56667 | W8: 153.5 | X8: 129.4 | Y8: 131.9 | Z8: 138.26667 | AA8: 129.4 | AB8: 123.6 | AC8: 126.5 | AD8: 116 | AE8: 126.6 | AF8: 121.3 | AG8: 136.8 | AH8: 125.9 | AI8: 134.2 | AJ8: 132.3
A9: Rural+Urban | B9: 2017 | C9: August | D9: 134.3 | E9: 143.4 | F9: 129.3 | G9: 139 | H9: 118.1 | I9: 145.5 | J9: 168.6 | K9: 132.7 | L9: 121.2 | M9: 135.6 | N9: 128.7 | O9: 146.8 | P9: 140.6 | Q9: 149.8 | R9: 138.11429 | S9: 140.3 | T9: 133 | U9: 139.3 | V9: 137.53333 | W9: 153.9 | X9: 129.8 | Y9: 132.8 | Z9: 138.83333 | AA9: 130.2 | AB9: 124.5 | AC9: 127.35 | AD9: 117.3 | AE9: 127.3 | AF9: 122.3 | AG9: 137.6 | AH9: 126.8 | AI9: 135.4 | AJ9: 133.26667
A10: Rural+Urban | B10: 2017 | C10: September | D10: 134.7 | E10: 142.4 | F10: 130.2 | G10: 139.6 | H10: 118.4 | I10: 143 | J10: 156.6 | K10: 132.9 | L10: 121.5 | M10: 135.6 | N10: 128.8 | O10: 147.3 | P10: 139 | Q10: 150.8 | R10: 137.2 | S10: 141.1 | T10: 133.4 | U10: 140 | V10: 138.16667 | W10: 154.8 | X10: 131 | Y10: 133.3 | Z10: 139.7 | AA10: 130.6 | AB10: 125.7 | AC10: 128.15 | AD10: 118.3 | AE10: 127.9 | AF10: 123.1 | AG10: 137.4 | AH10: 127.5 | AI10: 135.2 | AJ10: 133.36667
A11: Rural+Urban | B11: 2017 | C11: October | D11: 135.3 | E11: 142.2 | F11: 131.2 | G11: 140.6 | H11: 119 | I11: 141.5 | J11: 162.6 | K11: 132.3 | L11: 121.8 | M11: 136.3 | N11: 128.7 | O11: 148.1 | P11: 140.1 | Q11: 151.6 | R11: 137.95 | S11: 142 | T11: 134.1 | U11: 140.8 | V11: 138.96667 | W11: 155.6 | X11: 132.2 | Y11: 133.6 | Z11: 140.46667 | AA11: 131.3 | AB11: 126.2 | AC11: 128.75 | AD11: 117.8 | AE11: 128.4 | AF11: 123.1 | AG11: 137.9 | AH11: 127.7 | AI11: 136.1 | AJ11: 133.9
A12: Rural+Urban | B12: 2017 | C12: November | D12: 135.7 | E12: 142.4 | F12: 142.9 | G12: 140.8 | H12: 119.2 | I12: 142.2 | J12: 173.8 | K12: 131.2 | L12: 123 | M12: 136.8 | N12: 129.2 | O12: 148.9 | P12: 142.1 | Q12: 153.2 | R12: 140.1 | S12: 143 | T12: 134.8 | U12: 141.8 | V12: 139.86667 | W12: 154.7 | X12: 135.3 | Y12: 134.4 | Z12: 141.46667 | AA12: 132.6 | AB12: 126.8 | AC12: 129.7 | AD12: 118.3 | AE12: 128.9 | AF12: 123.6 | AG12: 138.6 | AH12: 128.4 | AI12: 137.6 | AJ12: 134.86667
A13: Rural+Urban | B13: 2017 | C13: December | D13: 135.8 | E13: 143.3 | F13: 145.2 | G13: 141 | H13: 120.5 | I13: 141.5 | J13: 161.7 | K13: 129.1 | L13: 121.5 | M13: 137.1 | N13: 128.8 | O13: 149 | P13: 140.5 | Q13: 154.2 | R13: 139.22857 | S13: 143.1 | T13: 135.1 | U13: 142 | V13: 140.06667 | W13: 155.5 | X13: 136.6 | Y13: 134.7 | Z13: 142.26667 | AA13: 133.1 | AB13: 126.5 | AC13: 129.8 | AD13: 118.5 | AE13: 129 | AF13: 123.75 | AG13: 138.5 | AH13: 128.6 | AI13: 137.2 | AJ13: 134.76667
... A35: Rural+Urban | B35: 2019 | C35: November | D35: 142.5 | E35: 163.2 | F35: 145.6 | G35: 146.7 | H35: 124.3 | I35: 147.4 | J35: 199.6 | K35: 135.7 | L35: 114.2 | M35: 147 | N35: 135.3 | O35: 157.5 | P35: 151.9 | Q35: 167.9 | R35: 148.48571 | S35: 149.9 | T35: 141 | U35: 148.6 | V35: 146.5 | W35: 175.6 | X35: 142.3 | Y35: 145.3 | Z35: 154.4 | AA35: 149.9 | AB35: 140.3 | AC35: 145.1 | AD35: 126.6 | AE35: 142.1 | AF35: 134.35 | AG35: 155.5 | AH35: 141.3 | AI35: 148.6 | AJ35: 148.46667
A36: Rural+Urban | B36: 2019 | C36: December | D36: 143.5 | E36: 165 | F36: 151.1 | G36: 148.3 | H36: 125.7 | I36: 145.7 | J36: 217 | K36: 138.3 | L36: 114 | M36: 148.7 | N36: 135.8 | O36: 158 | P36: 155 | Q36: 168.5 | R36: 151.04286 | S36: 150.3 | T36: 141.3 | U36: 149 | V36: 146.86667 | W36: 152.8 | X36: 143.7 | Y36: 145.8 | Z36: 144.75 | AA36: 150.4 | AB36: 140.4 | AC36: 145.4 | AD36: 129.8 | AE36: 142.3 | AF36: 136.05 | AG36: 155.7 | AH36: 142.5 | AI36: 150.4 | AJ36: 149.53333
A37: Rural+Urban | B37: 2020 | C37: January | D37: 144.3 | E37: 167.4 | F37: 154.9 | G37: 150.1 | H37: 129.9 | I37: 143.2 | J37: 197 | K37: 140.4 | L37: 114.1 | M37: 150.9 | N37: 136.1 | O37: 158.6 | P37: 153.5 | Q37: 169.2 | R37: 150.68571 | S37: 150.5 | T37: 141.5 | U37: 149.2 | V37: 147.06667 | W37: 153.9 | X37: 144.6 | Y37: 146.2 | Z37: 145.4 | AA37: 151.2 | AB37: 142.3 | AC37: 146.75 | AD37: 130.9 | AE37: 142.8 | AF37: 136.85 | AG37: 156.1 | AH37: 143.4 | AI37: 150.2 | AJ37: 149.9
A38: Rural+Urban | B38: 2020 | C38: February | D38: 144.8 | E38: 167.5 | F38: 151.8 | G38: 150.8 | H38: 131.4 | I38: 141.8 | J38: 170.7 | K38: 141.1 | L38: 113.6 | M38: 152 | N38: 136.5 | O38: 159.1 | P38: 150.5 | Q38: 170.1 | R38: 148.69286 | S38: 150.8 | T38: 141.7 | U38: 149.5 | V38: 147.33333 | W38: 154.8 | X38: 147.2 | Y38: 146.4 | Z38: 146.8 | AA38: 151.7 | AB38: 143.4 | AC38: 147.55 | AD38: 130.3 | AE38: 143.2 | AF38: 136.75 | AG38: 156.2 | AH38: 143.6 | AI38: 149.1 | AJ38: 149.63333
A39: Rural+Urban | B39: 2020 | C39: March | D39: 145.1 | E39: 167 | F39: 148.1 | G39: 151.5 | H39: 131.2 | I39: 142.5 | J39: 157.3 | K39: 141.1 | L39: 113.2 | M39: 153.2 | N39: 136.7 | O39: 159.6 | P39: 148.9 | Q39: 171.2 | R39: 147.61429 | S39: 151.2 | T39: 141.9 | U39: 149.8 | V39: 147.63333 | W39: 154.5 | X39: 148.9 | Y39: 146.4 | Z39: 147.65 | AA39: 152.3 | AB39: 145.2 | AC39: 148.75 | AD39: 129.9 | AE39: 143.7 | AF39: 136.8 | AG39: 156.1 | AH39: 143.8 | AI39: 148.6 | AJ39: 149.5
A40: Rural+Urban | B40: 2020 | C40: April | D40: 148.7 | E40: 156.26475 | F40: 148.8 | G40: 155.6 | H40: 135.1 | I40: 149.9 | J40: 168.6 | K40: 150.4 | L40: 120.3 | M40: 157.1 | N40: 136.8 | O40: 149.08716 | P40: 151.4 | Q40: 155.38579 | R40: 148.81698 | S40: 142.66366 | T40: 135.97732 | U40: 141.67432 | V40: 140.1051 | W40: 155.6 | X40: 144.1 | Y40: 136.68689 | Z40: 140.39344 | AA40: 150.7 | AB40: 133.35 | AC40: 142.025 | AD40: 127.17049 | AE40: 133.8918 | AF40: 130.53115 | AG40: 141.13115 | AH40: 134.23579 | AI40: 139.56448 | AJ40: 138.31047
A41: Rural+Urban | B41: 2020 | C41: May | D41: 136.68591 | E41: 156.26475 | F41: 140.79756 | G41: 140.3252 | H41: 132.12629 | I41: 140.84092 | J41: 155.75203 | K41: 141.43089 | L41: 110.92493 | M41: 144.52222 | N41: 134.09295 | O41: 149.08716 | P41: 142.51003 | Q41: 155.38579 | R41: 141.4819 | S41: 142.66366 | T41: 135.97732 | U41: 141.67432 | V41: 140.1051 | W41: 139.2561 | X41: 139.2561 | Y41: 136.68689 | Z41: 138.39969 | AA41: 138.5168 | AB41: 133.35 | AC41: 135.9334 | AD41: 127.17049 | AE41: 133.8918 | AF41: 130.53115 | AG41: 141.13115 | AH41: 134.23579 | AI41: 139.56448 | AJ41: 138.31047
A42: Rural+Urban | B42: 2020 | C42: June | D42: 149.6 | E42: 192.7 | F42: 151.4 | G42: 153.3 | H42: 136.3 | I42: 147.2 | J42: 156.5 | K42: 150.9 | L42: 114.2 | M42: 159.5 | N42: 139.4 | O42: 161.8 | P42: 154 | Q42: 183.5 | R42: 153.59286 | S42: 152.5 | T42: 144.4 | U42: 151.4 | V42: 149.43333 | W42: 154.7 | X42: 141.9 | Y42: 146.4 | Z42: 144.15 | AA42: 154.4 | AB42: 151.6 | AC42: 153 | AD42: 135 | AE42: 148.3 | AF42: 141.65 | AG42: 156.4 | AH42: 147 | AI42: 151.8 | AJ42: 151.73333
A43: Rural+Urban | B43: 2020 | C43: July | D43: 149.6 | E43: 192.7 | F43: 151.4 | G43: 153.3 | H43: 136.3 | I43: 147.2 | J43: 156.5 | K43: 150.9 | L43: 114.2 | M43: 159.5 | N43: 139.4 | O43: 161.8 | P43: 154 | Q43: 183.5 | R43: 153.59286 | S43: 152.5 | T43: 144.4 | U43: 151.4 | V43: 149.43333 | W43: 154.7 | X43: 141.9 | Y43: 146.4 | Z43: 144.15 | AA43: 154.4 | AB43: 151.6 | AC43: 153 | AD43: 135 | AE43: 148.3 | AF43: 141.65 | AG43: 156.4 | AH43: 147 | AI43: 151.8 | AJ43: 151.73333
A44: Rural+Urban | B44: 2020 | C44: August | D44: 148.9 | E44: 190.9 | F44: 150.8 | G44: 153.3 | H44: 137.4 | I44: 150.4 | J44: 178.1 | K44: 150.4 | L44: 115.1 | M44: 160 | N44: 140.6 | O44: 162.3 | P44: 157 | Q44: 182.6 | R44: 155.55714 | S44: 153.1 | T44: 143.4 | U44: 151.7 | V44: 149.4 | W44: 155.5 | X44: 143 | Y44: 148.4 | Z44: 145.7 | AA44: 155 | AB44: 154.3 | AC44: 154.65 | AD44: 138.5 | AE44: 146 | AF44: 142.25 | AG44: 158.5 | AH44: 149 | AI44: 153.9 | AJ44: 153.8
A45: Rural+Urban | B45: 2020 | C45: September | D45: 148.4 | E45: 187.1 | F45: 152.5 | G45: 153.6 | H45: 138.2 | I45: 150.9 | J45: 186.7 | K45: 149.8 | L45: 116.4 | M45: 160.3 | N45: 142.2 | O45: 162.9 | P45: 158 | Q45: 184.4 | R45: 156.52857 | S45: 153.4 | T45: 144.3 | U45: 152 | V45: 149.9 | W45: 156.3 | X45: 142.9 | Y45: 148.7 | Z45: 145.8 | AA45: 155.6 | AB45: 158.4 | AC45: 157 | AD45: 139.6 | AE45: 146.6 | AF45: 143.1 | AG45: 157.5 | AH45: 150 | AI45: 154.7 | AJ45: 154.06667
A46: Rural+Urban | B46: 2020 | C46: October | D46: 147.5 | E46: 188.9 | F46: 161.4 | G46: 153.6 | H46: 140.1 | I46: 151.2 | J46: 209.2 | K46: 150.9 | L46: 116.2 | M46: 161 | N46: 144 | O46: 163.2 | P46: 161.4 | Q46: 184.3 | R46: 159.49286 | S46: 153.7 | T46: 144.6 | U46: 152.3 | V46: 150.2 | W46: 156.5 | X46: 143.1 | Y46: 148.7 | Z46: 145.9 | AA46: 156.3 | AB46: 157 | AC46: 156.65 | AD46: 140.6 | AE46: 146.5 | AF46: 143.55 | AG46: 158.5 | AH46: 150.4 | AI46: 156.4 | AJ46: 155.1
A47: Rural+Urban | B47: 2020 | C47: November | D47: 146.8 | E47: 191 | F47: 173.6 | G47: 153.8 | H47: 142.7 | I47: 148.4 | J47: 230 | K47: 156.8 | L47: 115.7 | M47: 161.8 | N47: 146.5 | O47: 163.8 | P47: 164.7 | Q47: 184.8 | R47: 162.88571 | S47: 154.3 | T47: 144.9 | U47: 152.8 | V47: 150.66667 | W47: 158 | X47: 143.6 | Y47: 149.2 | Z47: 146.4 | AA47: 157.2 | AB47: 156.9 | AC47: 157.05 | AD47: 140.4 | AE47: 148.4 | AF47: 144.4 | AG47: 158.6 | AH47: 150.7 | AI47: 158.4 | AJ47: 155.9
A48: Rural+Urban | B48: 2020 | C48: December | D48: 146 | E48: 191 | F48: 175.3 | G48: 154.1 | H48: 146.6 | I48: 147.7 | J48: 230.5 | K48: 160.2 | L48: 115.3 | M48: 163 | N48: 149.2 | O48: 164.8 | P48: 165.4 | Q48: 185.4 | R48: 163.89286 | S48: 155 | T48: 145.4 | U48: 153.6 | V48: 151.33333 | W48: 158.4 | X48: 144.6 | Y48: 149.7 | Z48: 147.15 | AA48: 158.3 | AB48: 157.1 | AC48: 157.7 | AD48: 140.7 | AE48: 148.5 | AF48: 144.6 | AG48: 159.4 | AH48: 151.2 | AI48: 158.9 | AJ48: 156.5
A49: Rural+Urban | B49: 2021 | C49: January | D49: 144.9 | E49: 190.1 | F49: 175.3 | G49: 154.1 | H49: 150.9 | I49: 149.6 | J49: 194.2 | K49: 160.4 | L49: 114.6 | M49: 164 | N49: 151.8 | O49: 165.6 | P49: 161 | Q49: 186.5 | R49: 161.64286 | S49: 155.5 | T49: 146.1 | U49: 154.2 | V49: 151.93333 | W49: 157.7 | X49: 147.9 | Y49: 150 | Z49: 148.95 | AA49: 159.3 | AB49: 156.8 | AC49: 158.05 | AD49: 141.9 | AE49: 149.6 | AF49: 145.75 | AG49: 159.2 | AH49: 151.9 | AI49: 157.3 | AJ49: 156.13333
A50: Rural+Urban | B50: 2021 | C50: February | D50: 144.3 | E50: 186.5 | F50: 168.7 | G50: 154.7 | H50: 158.7 | I50: 150.7 | J50: 160 | K50: 158.8 | L50: 112.8 | M50: 164.2 | N50: 155.5 | O50: 167.5 | P50: 156.9 | Q50: 188.3 | R50: 159.11429 | S50: 157.2 | T50: 147.4 | U50: 155.8 | V50: 153.46667 | W50: 159.8 | X50: 152.4 | Y50: 150.9 | Z50: 151.65 | AA50: 161.3 | AB50: 155.8 | AC50: 158.55 | AD50: 145.1 | AE50: 151.5 | AF50: 148.3 | AG50: 159.5 | AH50: 153.4 | AI50: 156.6 | AJ50: 156.5
A51: Rural+Urban | B51: 2021 | C51: March | D51: 144.1 | E51: 192.2 | F51: 163.8 | G51: 154.9 | H51: 163.9 | I51: 153.7 | J51: 149.5 | K51: 159.8 | L51: 112.6 | M51: 163.5 | N51: 156.5 | O51: 168.2 | P51: 156.7 | Q51: 188.1 | R51: 159.10714 | S51: 157.8 | T51: 147.9 | U51: 156.4 | V51: 154.03333 | W51: 159.9 | X51: 155.5 | Y51: 151.2 | Z51: 153.35 | AA51: 161.7 | AB51: 153.8 | AC51: 157.75 | AD51: 146.2 | AE51: 152.6 | AF51: 149.4 | AG51: 160.2 | AH51: 153.8 | AI51: 156.8 | AJ51: 156.93333
A52: Rural+Urban | B52: 2021 | C52: April | D52: 144.3 | E52: 198 | F52: 164.6 | G52: 155.4 | H52: 170.1 | I52: 164.4 | J52: 144.1 | K52: 161.7 | L52: 113.1 | M52: 163.9 | N52: 157.6 | O52: 168.9 | P52: 158 | Q52: 188.8 | R52: 160.92143 | S52: 158.8 | T52: 148.5 | U52: 157.3 | V52: 154.86667 | W52: 161.4 | X52: 155.6 | Y52: 151.8 | Z52: 153.7 | AA52: 162.3 | AB52: 155.4 | AC52: 158.85 | AD52: 146.6 | AE52: 153.2 | AF52: 149.9 | AG52: 160.3 | AH52: 154.4 | AI52: 157.8 | AJ52: 157.5
A53: Rural+Urban | B53: 2021 | C53: May | D53: 146.3 | E53: 200.5 | F53: 170.3 | G53: 156.1 | H53: 178.7 | I53: 167.1 | J53: 147.9 | K53: 165.4 | L53: 114.8 | M53: 168.2 | N53: 159.3 | O53: 170.4 | P53: 160.7 | Q53: 191.9 | R53: 164.11429 | S53: 161.8 | T53: 152.1 | U53: 160.4 | V53: 158.1 | W53: 161.6 | X53: 159.4 | Y53: 154.7 | Z53: 157.05 | AA53: 165.8 | AB53: 158.6 | AC53: 162.2 | AD53: 148.9 | AE53: 155.8 | AF53: 152.35 | AG53: 161.2 | AH53: 156.8 | AI53: 160.4 | AJ53: 159.46667
... A77: Rural+Urban | B77: 2023 | C77: May | D77: 173.7 | E77: 214.3 | F77: 173.2 | G77: 179.5 | H77: 170 | I77: 172.2 | J77: 161 | K77: 175.6 | L77: 122.7 | M77: 218 | N77: 173.4 | O77: 194.2 | P77: 179.1 | Q77: 201 | R77: 179.13571 | S77: 187.3 | T77: 179.7 | U77: 186.2 | V77: 184.4 | W77: 175.6 | X77: 182.8 | Y77: 175.2 | Z77: 179 | AA77: 185.7 | AB77: 185.2 | AC77: 185.45 | AD77: 164.8 | AE77: 171.2 | AF77: 168 | AG77: 177.1 | AH77: 175.7 | AI77: 179.1 | AJ77: 177.3
B79: 2017 | D79: 3 | E79: 5.1 | F79: 13 | G79: 5.6 | H79: 1.4 | I79: 8.5 | J79: 42.3 | K79: -30.4 | L79: 5.9 | M79: -2.5 | N79: 2.2 | O79: 6.2 | P79: 7.4 | Q79: 10.4 | R79: 5.5785714 | S79: 6.5 | T79: 4.9 | U79: 6.4 | V79: 5.9333333 | W79: 7.8 | X79: 9.8 | Y79: 5.3 | Z79: 7.6333333 | AA79: 6 | AB79: 4.8 | AC79: 5.4 | AD79: 1.5 | AE79: 4.8 | AF79: 3.15 | AG79: 5.2 | AH79: 4.2 | AI79: 6.9 | AJ79: 5.4333333
B80: 2018 | D80: 1.5 | E80: 6.3 | F80: -4.9 | G80: 1 | H80: 1.3 | I80: -1.9 | J80: -16.4 | K80: -7.5 | L80: -8.5 | M80: 3.1 | N80: 4.8 | O80: 5.1 | P80: -1 | Q80: 8.3 | R80: -0.62857143 | S80: 4.6 | T80: 3.9 | U80: 4.5 | V80: 4.3333333 | W80: 9.2 | X80: 6.1 | Y80: 8.3 | Z80: 7.8666667 | AA80: 11.6 | AB80: 4.9 | AC80: 8.25 | AD80: 4.3 | AE80: 7.1 | AF80: 5.7 | AG80: 11.1 | AH80: 7.7 | AI80: 3.2 | AJ80: 7.3333333
B81: 2019 | D81: 6.4 | E81: 13.6 | F81: 10.9 | G81: 6.2 | H81: 3.9 | I81: 10.3 | J81: 85.7 | K81: 18 | L81: 4.9 | M81: 9.3 | N81: 2.5 | O81: 3.4 | P81: 17.6 | Q81: 5.3 | R81: 14.142857 | S81: 2.7 | T81: 2.3 | U81: 2.6 | V81: 2.5333333 | W81: -12.5 | X81: 4.2 | Y81: 2.2 | Z81: -4.7166667 | AA81: 5.3 | AB81: 7.6 | AC81: 6.45 | AD81: 6.5 | AE81: 5.6 | AF81: 6.05 | AG81: 5.5 | AH81: 5.6 | AI81: 10.8 | AJ81: 7.3
B82: 2020 | D82: 1.7 | E82: 23.6 | F82: 20.4 | G82: 4 | H82: 16.7 | I82: 4.5 | J82: 33.5 | K82: 19.8 | L82: 1.2 | M82: 12.1 | N82: 13.1 | O82: 6.2 | P82: 11.9 | Q82: 16.2 | R82: 13.207143 | S82: 4.5 | T82: 3.9 | U82: 4.4 | V82: 4.2666667 | W82: 4.5 | X82: 0 | Y82: 3.5 | Z82: 1.75 | AA82: 7.1 | AB82: 14.8 | AC82: 10.95 | AD82: 9.8 | AE82: 5.7 | AF82: 7.75 | AG82: 3.3 | AH82: 7.8 | AI82: 8.7 | AJ82: 6.6
B83: 2021 | D83: 3.8 | E83: 8.7 | F83: 2.6 | G83: 5.8 | H83: 36.7 | I83: 5.3 | J83: -5.9 | K83: 4 | L83: 6.4 | M83: 6.5 | N83: 12.4 | O83: 10.9 | P83: 7.2 | Q83: 5.9 | R83: 7.8785714 | S83: 13 | T83: 12.6 | U83: 12.8 | V83: 12.8 | W83: 5.7 | X83: 16.2 | Y83: 10.2 | Z83: 13.2 | AA83: 11.3 | AB83: 5.8 | AC83: 8.55 | AD83: 13.8 | AE83: 11 | AF83: 12.4 | AG83: 5.2 | AH83: 10.1 | AI83: 8.9 | AJ83: 8.0666667
B84: 2022 | D84: 19.7 | E84: 10.3 | F84: 11.4 | G84: 13.1 | H84: 3.8 | I84: 4.3 | J84: -14.4 | K84: 6.9 | L84: 1.8 | M84: 33.1 | N84: 6.7 | O84: 13 | P84: 9.5 | Q84: 5.1 | R84: 8.8785714 | S84: 14.1 | T84: 16.3 | U84: 14.5 | V84: 14.966667 | W84: 6.2 | X84: 17.8 | Y84: 11 | Z84: 14.4 | AA84: 9.7 | AB84: 12.8 | AC84: 11.25 | AD84: 6.9 | AE84: 7.7 | AF84: 7.3 | AG84: 9.4 | AH84: 9.3 | AI84: 10 | AJ84: 9.5666667
B85: 2023 | D85: -0.1 | E85: 3.6 | F85: -21.3 | G85: 4.9 | H85: -17.2 | I85: 13.9 | J85: 7.1 | K85: 4.7 | L85: 1.6 | M85: 9.6 | N85: 2 | O85: 3 | P85: 2.4 | Q85: 2.8 | R85: 1.2142857 | S85: 2.4 | T85: 2.1 | U85: 2.4 | V85: 2.3 | W85: 3.5 | X85: 0.8 | Y85: 2.3 | Z85: 1.55 | AA85: 3.4 | AB85: 6.6 | AC85: 5 | AD85: 1.2 | AE85: 1.7 | AF85: 1.45 | AG85: 2.8 | AH85: 2.9 | AI85: 2.6 | AJ85: 2.7666667
...

Sheet Solution 3
A1: Sector | B1: Year | C1: Month | D1: Cereals and products | E1: Meat and fish | F1: Egg | G1: Milk and products | H1: Oils and fats | I1: Fruits | J1: Vegetables | K1: Pulses and products | L1: Sugar and Confectionery | M1: Spices | N1: Nonalcoholic beverages | O1: Prepared meals, scks, sweets etc. | P1: Food and beverages | Q1: Pan, tobacco and intoxicants | R1: food | S1: M-o-M inflation
A2: Rural+Urban | B2: 2022 | C2: May | D2: 154.1 | E2: 217 | F2: 162.4 | G2: 164.9 | H2: 202.4 | I2: 171 | J2: 174.9 | K2: 164.7 | L2: 119.7 | M2: 184.9 | N2: 167.1 | O2: 182.5 | P2: 173.3 | Q2: 194.1 | R2: 173.78571
A3: Rural+Urban | B3: 2022 | C3: June | D3: 155 | E3: 219.4 | F3: 170.8 | G3: 165.8 | H3: 200.9 | I3: 169.7 | J3: 182.3 | K3: 164.3 | L3: 119.9 | M3: 187.1 | N3: 167.9 | O3: 183.9 | P3: 174.9 | Q3: 194.3 | R3: 175.44286 | S3: =(R3-R2)/R2 -> 0.0095355528
A4: Rural+Urban | B4: 2022 | C4: July | D4: 156.5 | E4: 213 | F4: 175.2 | G4: 166.6 | H4: 195.8 | I4: 174.2 | J4: 182.1 | K4: 164.3 | L4: 120 | M4: 190 | N4: 168.4 | O4: 185.2 | P4: 175 | Q4: 194.6 | R4: 175.77857 | S4: =(R4-R3)/R3 -> 0.001913525
